<?xml version="1.0"?>
<robot xmlns:xacro="http://ros.org/wiki/xacro">

  <!-- Materials -->
  <material name="white">
    <color rgba="1 1 1 1" />
  </material>

  <material name="red">
    <color rgba="1 0 0 1" />
  </material>

  <material name="green">
    <color rgba="0 1 0 1" />
  </material>

  <material name="blue">
    <color rgba="0 0 1 1" />
  </material>

  <material name="yellow">
    <color rgba="1 1 0 1" />
  </material>

  <material name="black">
    <color rgba="0 0 0 1" />
  </material>

  <material name="SaxionGreen">
    <color rgba="0 0.612 0.510 1" />
  </material>

  <!-- Inertia Macros -->
  <xacro:macro name="box_inertia" params="m w h d">
    <inertial>
      <!-- Orientation may be adjusted based on your modeling convention -->
      <origin xyz="0 0 0" rpy="${pi/2} 0 ${pi/2}" />
      <mass value="${m}" />
      <inertia ixx="${(m/12) * (h*h + d*d)}" ixy="0.0" ixz="0.0" iyy="${(m/12) * (w*w + d*d)}" iyz="0.0" izz="${(m/12) * (w*w + h*h)}" />
    </inertial>
  </xacro:macro>

  <xacro:macro name="cylinder_inertia" params="m r h">
    <inertial>
      <origin xyz="0 0 0" rpy="${pi/2} 0 0" />
      <mass value="${m}" />
      <inertia ixx="${(m/12) * (3*r*r + h*h)}" ixy="0" ixz="0" iyy="${(m/12) * (3*r*r + h*h)}" iyz="0" izz="${(m/2) * (r*r)}" />
    </inertial>
  </xacro:macro>

  <!-- Wheel Macro -->
  <!-- 
       The macro takes a wheel name and an offset (x,y,z) relative to the base_link.
       Here, x_offset is chosen as half the wheel_base (front wheels: +, rear: -).
       y_offset is half the wheel_track (left: positive, right: negative).
       z_offset is set so that the wheel center is at the ground level (z = wheel_radius).
  -->
  <xacro:macro name="wheel" params="name x_offset y_offset z_offset is_right">
    <link name="${name}">
      <visual>
        <!-- Rotate the cylinder so its axis (default along z) aligns with the desired rolling axis -->
        <origin xyz="0 0 0" rpy="${pi} 0 ${pi/2}" />
        <geometry>
          <!-- <cylinder radius="${wheel_radius}" length="${wheel_thickness}" /> -->
          <mesh filename="package://vector_description/meshes/vector_wheel.dae" />
        </geometry>
        <!-- <material name="black">
          <color rgba="0 0 0 1" />
        </material> -->
      </visual>
      <collision>
        <origin xyz="0 0 -0.023" rpy="0 0 ${pi/2}" />
        <geometry>
          <cylinder radius="${wheel_radius}" length="${wheel_thickness}" />
        </geometry>
        <surface>
          <friction>
            <ode>
              <mu>0.8</mu>
              <mu2>0.8</mu2>
            </ode>
          </friction>
        </surface>
      </collision>
      <!-- Use cylinder_inertia for the wheel (mass = 1.15) -->
      <xacro:cylinder_inertia m="0.3" r="${wheel_radius}" h="${wheel_thickness}" />
    </link>
    <joint name="${name}_joint" type="continuous">
      <parent link="base_link" />
      <child link="${name}" />

      <xacro:if value="${is_right}">
        <origin xyz="${x_offset} ${y_offset} ${z_offset}" rpy="${pi/2} 0 0" />
        <axis xyz="0 0 -1" />
      </xacro:if>
      <xacro:unless value="${is_right}">
        <origin xyz="${x_offset} ${y_offset} ${z_offset}" rpy="${-pi/2} 0 ${0}" />
        <axis xyz="0 0 1" />
      </xacro:unless>
      <limit effort="1.0" velocity="1000000000"/>
      <dynamics damping="0.00000000000000000001" friction="0.0000000001"/>
    </joint>
  </xacro:macro>

</robot>